Workbook

Sheet Prestação de Contas
A1: Vida Plena S.A. — Prestação de Contas Corporativas
A2: Relatório Detalhado de Solicitações de Reembolso e Despesas Corporativas
A4: ID da Solicitação | B4: Data da Despesa | C4: Data da Solicitação | D4: Nome do Colaborador | E4: Matrícula | F4: Departamento | G4: Gestor Responsável | H4: Centro de Custo | I4: Cidade | J4: Estado | K4: Tipo de Despesa | L4: Descrição | M4: Valor (R$) | N4: Forma de Pagamento | O4: Possui Nota Fiscal | P4: Número da Nota Fiscal | Q4: Status | R4: Data da Aprovação | S4: Responsável pela Aprovação | T4: Observações
A5: SOL-2026-001 | B5: 46027 | C5: 46029 | D5: Carlos Eduardo Silva | E5: VP-1024 | F5: Comercial | G5: Roberto Alves | H5: CC101 | I5: São Paulo | J5: SP | K5: Hospedagem | L5: Hospedagem cliente Itaú - 2 diárias | M5: 680 | N5: Cartão Corporativo | O5: Sim | P5: NF-88412 | Q5: Aprovado | R5: 46030 | S5: Roberto Alves | T5: Dentro do limite corporativo aprovado
A6: SOL-2026-002 | B6: 46028 | C6: 46029 | D6: Mariana Costa | E6: VP-1105 | F6: TI | G6: Beatriz Lima | H6: CC201 | I6: Campinas | J6: SP | K6: Uber | L6: Deslocamento para visita técnica no Data Center | M6: 85.5 | N6: Reembolso | O6: Sim | P6: NF-10492 | Q6: Aprovado | R6: 46030 | S6: Beatriz Lima | T6: Conforme comprovante anexado
A7: SOL-2026-003 | B7: 46030 | C7: 46032 | D7: Lucas Fernandes | E7: VP-1089 | F7: Financeiro | G7: Fernando Rocha | H7: CC301 | I7: Rio de Janeiro | J7: RJ | K7: Passagem Aérea | L7: Voo para reunião trimestral de controladoria | M7: 1250 | N7: Faturamento Direct | O7: Sim | P7: NF-99210 | Q7: Aprovado | R7: 46033 | S7: Fernando Rocha | T7: Viagem emergencial autorizada
A8: SOL-2026-004 | B8: 46032 | C8: 46033 | D8: Camila Rocha | E8: VP-1142 | F8: RH | G8: Patricia Mendes | H8: CC401 | I8: São Paulo | J8: SP | K8: Alimentação | L8: Almoço de integração com novos contratados | M8: 185 | N8: Reembolso | O8: Sim | P8: NF-44123 | Q8: Aprovado | R8: 46034 | S8: Patricia Mendes | T8: Aprovado exceção de limite por gestor
A9: SOL-2026-005 | B9: 46034 | C9: 46035 | D9: Rafael Almeida | E9: VP-1201 | F9: Compliance | G9: Gustavo Carvalho | H9: CC501 | I9: Brasília | J9: DF | K9: Passagem Rodoviária | L9: Deslocamento para auditoria regulatória | M9: 210 | N9: Reembolso | O9: Sim | P9: NF-00312 | Q9: Aprovado | R9: 46036 | S9: Gustavo Carvalho | T9: Comprovante válido
A10: SOL-2026-006 | B10: 46036 | C10: 46037 | D10: Juliana Martins | E10: VP-1055 | F10: Comunicação | G10: Vanessa Souza | H10: CC601 | I10: São Paulo | J10: SP | K10: Eventos Corporativos | L10: Inscrição no Workshop de Comunicação Integrada | M10: 890 | N10: Cartão Corporativo | O10: Sim | P10: NF-77219 | Q10: Aprovado | R10: 46038 | S10: Vanessa Souza | T10: Treinamento previsto no orçamento
A11: SOL-2026-007 | B11: 46037 | C11: 46038 | D11: Felipe Santos | E11: VP-1230 | F11: Comercial | G11: Roberto Alves | H11: CC102 | I11: Belo Horizonte | J11: MG | K11: Alimentação | L11: Jantar de negócios com prospect | M11: 240 | N11: Reembolso | O11: Não | P11: - | Q11: Rejeitado | R11: - | S11: - | T11: Falta nota fiscal original fiscal emitida
A12: SOL-2026-008 | B12: 46039 | C12: 46040 | D12: Beatriz Lima | E12: VP-1008 | F12: TI | G12: Beatriz Lima | H12: CC201 | I12: São Paulo | J12: SP | K12: Cursos | L12: Certificação AWS Solutions Architect | M12: 1450 | N12: Cartão Corporativo | O12: Sim | P12: NF-55102 | Q12: Aprovado | R12: 46041 | S12: Diretoria | T12: Aprovado pelo Diretor de Tecnologia
A13: SOL-2026-009 | B13: 46040 | C13: 46041 | D13: Thiago Oliveira | E13: VP-1288 | F13: Financeiro | G13: Fernando Rocha | H13: CC302 | I13: São Paulo | J13: SP | K13: Material de Escritório | L13: Compra de suprimentos de urgência para tesouraria | M13: 145.2 | N13: Reembolso | O13: Sim | P13: NF-11234 | Q13: Aprovado | R13: 46042 | S13: Fernando Rocha | T13: Material recebido pelo estoque
A14: SOL-2026-010 | B14: 46042 | C14: 46043 | D14: Amanda Ribeiro | E14: VP-1190 | F14: RH | G14: Patricia Mendes | H14: CC402 | I14: Curitiba | J14: PR | K14: Combustível | L14: Visita a unidade regional de Curitiba | M14: 230 | N14: Reembolso | O14: Sim | P14: NF-88192 | Q14: Aprovado | R14: 46044 | S14: Patricia Mendes | T14: Km rodado conforme relatório
A15: SOL-2026-011 | B15: 46044 | C15: 46045 | D15: Rodrigo Nogueira | E15: VP-1310 | F15: Comercial | G15: Roberto Alves | H15: CC101 | I15: Porto Alegre | J15: RS | K15: Hospedagem | L15: Diária de hotel durante feira comercial | M15: 520 | N15: Cartão Corporativo | O15: Sim | P15: NF-33910 | Q15: Aprovado | R15: 46046 | S15: Roberto Alves | T15: Valor excedeu limite em R$20 (aprovado)
A16: SOL-2026-012 | B16: 46046 | C16: 46047 | D16: Gabriela Dias | E16: VP-1255 | F16: TI | G16: Beatriz Lima | H16: CC202 | I16: São Paulo | J16: SP | K16: Táxi | L16: Deslocamento após expediente estendido | M16: 65 | N16: Reembolso | O16: Sim | P16: NF-22109 | Q16: Aprovado | R16: 46048 | S16: Beatriz Lima | T16: Autorizado por hora extra
A17: SOL-2026-013 | B17: 46047 | C17: 46048 | D17: Marcelo Souza | E17: VP-1177 | F17: Compliance | G17: Gustavo Carvalho | H17: CC501 | I17: São Paulo | J17: SP | K17: Estacionamento | L17: Estacionamento reunião com auditores externos | M17: 75 | N17: Reembolso | O17: Sim | P17: NF-90812 | Q17: Aprovado | R17: 46049 | S17: Gustavo Carvalho | T17: Reembolso padrão
A18: SOL-2026-014 | B18: 46049 | C18: 46050 | D18: Fernanda Lima | E18: VP-1040 | F18: Comunicação | G18: Vanessa Souza | H18: CC601 | I18: Rio de Janeiro | J18: RJ | K18: Uber | L18: Deslocamento para cobertura de evento corporativo | M18: 110 | N18: Reembolso | O18: Sim | P18: NF-66120 | Q18: Aprovado | R18: 46051 | S18: Vanessa Souza | T18: Dentro do limite
A19: SOL-2026-015 | B19: 46050 | C19: 46051 | D19: Carlos Eduardo Silva | E19: VP-1024 | F19: Comercial | G19: Roberto Alves | H19: CC101 | I19: São Paulo | J19: SP | K19: Alimentação | L19: Almoço individual em viagem de negócios | M19: 95 | N19: Reembolso | O19: Sim | P19: NF-44910 | Q19: Aprovado | R19: 46052 | S19: Roberto Alves | T19: Dentro do limite
A20: SOL-2026-016 | B20: 46054 | C20: 46055 | D20: Pedro Henrique | E20: VP-1350 | F20: Financeiro | G20: Fernando Rocha | H20: CC301 | I20: São Paulo | J20: SP | K20: Pedágio | L20: Deslocamento de carro particular para filial | M20: 42.8 | N20: Reembolso | O20: Sim | P20: NF-11029 | Q20: Aprovado | R20: 46056 | S20: Fernando Rocha | T20: Comprovante de pedágio anexado
A21: SOL-2026-017 | B21: 46055 | C21: 46056 | D21: Mariana Costa | E21: VP-1105 | F21: TI | G21: Beatriz Lima | H21: CC201 | I21: São Paulo | J21: SP | K21: Material de Escritório | L21: Periféricos de informática de emergência | M21: 320 | N21: Reembolso | O21: Não | P21: - | Q21: Rejeitado | R21: - | S21: - | T21: Ausência de Nota Fiscal com CNPJ da empresa
A22: SOL-2026-018 | B22: 46057 | C22: 46058 | D22: Lucas Fernandes | E22: VP-1089 | F22: Financeiro | G22: Fernando Rocha | H22: CC301 | I22: Belo Horizonte | J22: MG | K22: Hospedagem | L22: Hospedagem reunião fiscal regional | M22: 480 | N22: Cartão Corporativo | O22: Sim | P22: NF-77312 | Q22: Aprovado | R22: 46059 | S22: Fernando Rocha | T22: Dentro do limite
A23: SOL-2026-019 | B23: 46058 | C23: 46059 | D23: Camila Rocha | E23: VP-1142 | F23: RH | G23: Patricia Mendes | H23: CC401 | I23: São Paulo | J23: SP | K23: Cursos | L23: Workshop de Gestão por Competências | M23: 750 | N23: Cartão Corporativo | O23: Sim | P23: NF-88210 | Q23: Aprovado | R23: 46060 | S23: Patricia Mendes | T23: Treinamento interno
A24: SOL-2026-020 | B24: 46060 | C24: 46061 | D24: Felipe Santos | E24: VP-1230 | F24: Comercial | G24: Roberto Alves | H24: CC102 | I24: Salvador | J24: BA | K24: Passagem Aérea | L24: Passagem para prospeção de grandes contas | M24: 1380 | N24: Faturamento Direct | O24: Sim | P24: NF-10293 | Q24: Aprovado | R24: 46062 | S24: Roberto Alves | T24: Aprovado conforme política
A25: SOL-2026-021 | B25: 46061 | C25: 46062 | D25: Rafael Almeida | E25: VP-1201 | F25: Compliance | G25: Gustavo Carvalho | H25: CC501 | I25: São Paulo | J25: SP | K25: Uber | L25: Deslocamento reunião Faria Lima | M25: 48 | N25: Reembolso | O25: Sim | P25: NF-55410 | Q25: Aprovado | R25: 46063 | S25: Gustavo Carvalho | T25: Ok
A26: SOL-2026-022 | B26: 46063 | C26: 46064 | D26: Juliana Martins | E26: VP-1055 | F26: Comunicação | G26: Vanessa Souza | H26: CC601 | I26: São Paulo | J26: SP | K26: Alimentação | L26: Jantar de alinhamento com agência de imprensa | M26: 210 | N26: Reembolso | O26: Sim | P26: NF-99482 | Q26: Rejeitado | R26: - | S26: - | T26: Valor acima do limite sem justificativa prévia
A27: SOL-2026-023 | B27: 46065 | C27: 46066 | D27: Thiago Oliveira | E27: VP-1288 | F27: Financeiro | G27: Fernando Rocha | H27: CC302 | I27: São Paulo | J27: SP | K27: Estacionamento | L27: Estacionamento idas ao banco central regional | M27: 60 | N27: Reembolso | O27: Sim | P27: NF-33219 | Q27: Aprovado | R27: 46067 | S27: Fernando Rocha | T27: Conforme comprovantes
A28: SOL-2026-024 | B28: 46067 | C28: 46068 | D28: Amanda Ribeiro | E28: VP-1190 | F28: RH | G28: Patricia Mendes | H28: CC402 | I28: São Paulo | J28: SP | K28: Uber | L28: Uber para visita domiciliar de assistência social | M28: 52.3 | N28: Reembolso | O28: Sim | P28: NF-66391 | Q28: Aprovado | R28: 46069 | S28: Patricia Mendes | T28: Aprovado
A29: SOL-2026-025 | B29: 46068 | C29: 46069 | D29: Rodrigo Nogueira | E29: VP-1310 | F29: Comercial | G29: Roberto Alves | H29: CC101 | I29: Curitiba | J29: PR | K29: Combustível | L29: Reembolso de gasolina rota de clientes PR | M29: 290 | N29: Reembolso | O29: Sim | P29: NF-88201 | Q29: Aprovado | R29: 46070 | S29: Roberto Alves | T29: Aprovado com relatório de Km
A30: SOL-2026-026 | B30: 46071 | C30: 46072 | D30: Gabriela Dias | E30: VP-1255 | F30: TI | G30: Beatriz Lima | H30: CC202 | I30: São Paulo | J30: SP | K30: Alimentação | L30: Lanche da equipe durante migração de servidor | M30: 160 | N30: Cartão Corporativo | O30: Sim | P30: NF-11928 | Q30: Aprovado | R30: 46073 | S30: Beatriz Lima | T30: Trabalho extraordinário autorização IT
A31: SOL-2026-027 | B31: 46073 | C31: 46074 | D31: Marcelo Souza | E31: VP-1177 | F31: Compliance | G31: Gustavo Carvalho | H31: CC501 | I31: Brasília | J31: DF | K31: Hospedagem | L31: Hospedagem acompanhamento de processo administrativo | M31: 490 | N31: Cartão Corporativo | O31: Sim | P31: NF-77401 | Q31: Aprovado | R31: 46075 | S31: Gustavo Carvalho | T31: Dentro do limite diário
A32: SOL-2026-028 | B32: 46075 | C32: 46076 | D32: Fernanda Lima | E32: VP-1040 | F32: Comunicação | G32: Vanessa Souza | H32: CC602 | I32: São Paulo | J32: SP | K32: Eventos Corporativos | L32: Aluguel de equipamento audiovisual para Live Anual | M32: 2300 | N32: Faturamento Direct | O32: Sim | P32: NF-50129 | Q32: Aprovado | R32: 46077 | S32: Vanessa Souza | T32: Aprovado diretoria de comunicação
A33: SOL-2026-029 | B33: 46077 | C33: 46078 | D33: Carlos Eduardo Silva | E33: VP-1024 | F33: Comercial | G33: Roberto Alves | H33: CC101 | I33: Campinas | J33: SP | K33: Pedágio | L33: Visita comercial Unicamp / Polo tecnológico | M33: 38.5 | N33: Reembolso | O33: Sim | P33: NF-99201 | Q33: Aprovado | R33: 46079 | S33: Roberto Alves | T33: Pedágio aprovado
A34: SOL-2026-030 | B34: 46078 | C34: 46079 | D34: Pedro Henrique | E34: VP-1350 | F34: Financeiro | G34: Fernando Rocha | H34: CC301 | I34: São Paulo | J34: SP | K34: Uber | L34: Uber reuniões externas de conciliação bancária | M34: 72 | N34: Reembolso | O34: Sim | P34: NF-12039 | Q34: Aprovado | R34: 46080 | S34: Fernando Rocha | T34: Ok
A35: SOL-2026-02-27 | B35: 46080 | C35: 46081 | D35: Lucas Fernandes | E35: VP-1089 | F35: Financeiro | G35: Fernando Rocha | H35: CC301 | I35: São Paulo | J35: SP | K35: Alimentação | L35: Almoço com consultoria de auditoria externa | M35: 140 | N35: Reembolso | O35: Sim | P35: NF-88301 | Q35: Aprovado | R35: 46082 | S35: Fernando Rocha | T35: Excesso justificado pelo número de pessoas
A36: SOL-2026-032 | B36: 46082 | C36: 46083 | D36: Mariana Costa | E36: VP-1105 | F36: TI | G36: Beatriz Lima | H36: CC201 | I36: São Paulo | J36: SP | K36: Cursos | L36: Curso avançado de Segurança da Informação | M36: 1800 | N36: Cartão Corporativo | O36: Sim | P36: NF-33210 | Q36: Aprovado | R36: 46084 | S36: Beatriz Lima | T36: Capacitação aprovada no plano anual
A37: SOL-2026-033 | B37: 46084 | C37: 46085 | D37: Camila Rocha | E37: VP-1142 | F37: RH | G37: Patricia Mendes | H37: CC401 | I37: São Paulo | J37: SP | K37: Material de Escritório | L37: Suprimentos para treinamento de integração | M37: 215 | N37: Reembolso | O37: Sim | P37: NF-44012 | Q37: Aprovado | R37: 46086 | S37: Patricia Mendes | T37: Nota fiscal conferida
A38: SOL-2026-034 | B38: 46086 | C38: 46087 | D38: Felipe Santos | E38: VP-1230 | F38: Comercial | G38: Roberto Alves | H38: CC102 | I38: Goiânia | J38: GO | K38: Passagem Aérea | L38: Passagem aérea prospecção Centro-Oeste | M38: 1150 | N38: Faturamento Direct | O38: Sim | P38: NF-99301 | Q38: Aprovado | R38: 46088 | S38: Roberto Alves | T38: Aprovado conforme fluxo
A39: SOL-2026-035 | B39: 46087 | C39: 46088 | D39: Rafael Almeida | E39: VP-1201 | F39: Compliance | G39: Gustavo Carvalho | H39: CC501 | I39: São Paulo | J39: SP | K39: Táxi | L39: Deslocamento ao Fórum Trabalhista | M39: 55 | N39: Reembolso | O39: Sim | P39: NF-22310 | Q39: Aprovado | R39: 46089 | S39: Gustavo Carvalho | T39: Ok
A40: SOL-2026-036 | B40: 46089 | C40: 46090 | D40: Juliana Martins | E40: VP-1055 | F40: Comunicação | G40: Vanessa Souza | H40: CC601 | I40: São Paulo | J40: SP | K40: Uber | L40: Uber para retirada de brindes corporativos | M40: 45 | N40: Reembolso | O40: Sim | P40: NF-77102 | Q40: Pendente | R40: - | S40: - | T40: Aguardando aprovação da gestão
A41: SOL-2026-037 | B41: 46091 | C41: 46092 | D41: Thiago Oliveira | E41: VP-1288 | F41: Financeiro | G41: Fernando Rocha | H41: CC302 | I41: São Paulo | J41: SP | K41: Alimentação | L41: Refeição em dia de fechamento contábil | M41: 65 | N41: Reembolso | O41: Sim | P41: NF-88219 | Q41: Pendente | R41: - | S41: - | T41: Aguardando aprovação da gestão
...

Sheet Centros de Custos
A1: Vida Plena S.A. — Tabela de Centros de Custos
A2: Estrutura Organizacional e Gestão de Custos por Departamento
A4: Código | B4: Centro de Custo | C4: Departamento | D4: Responsável
A5: CC101 | B5: Vendas Nacionais | C5: Comercial | D5: Roberto Alves
A6: CC102 | B6: Novos Negócios & Expansion | C6: Comercial | D6: Roberto Alves
A7: CC201 | B7: Infraestrutura & Cloud | C7: TI | D7: Beatriz Lima
A8: CC202 | B8: Sistemas & Desenvolvimento | C8: TI | D8: Beatriz Lima
A9: CC301 | B9: Controladoria & Contabilidade | C9: Financeiro | D9: Fernando Rocha
A10: CC302 | B10: Tesouraria & Planejamento | C10: Financeiro | D10: Fernando Rocha
A11: CC401 | B11: Atração & Seleção | C11: RH | D11: Patricia Mendes
A12: CC402 | B12: Desenvolvimento & Cultura | C12: RH | D12: Patricia Mendes
A13: CC501 | B13: Compliance & Jurídico | C13: Compliance | D13: Gustavo Carvalho
A14: CC502 | B14: Auditoria Interna & Riscos | C14: Compliance | D14: Gustavo Carvalho
A15: CC601 | B15: Comunicação Interna & Mídia | C15: Comunicação | D15: Vanessa Souza
... A19: CC801 | B19: Pesquisa & Desenvolvimento | C19: P&D | D19: Helena Castro

Sheet Limites de Reembolso
A1: Vida Plena S.A. — Política de Limites de Reembolso
A2: Diretrizes e Teto Máximo Permitido por Categoria de Despesa
A4: Tipo de Despesa | B4: Limite Máximo (R$) | C4: Necessita Aprovação Especial | D4: Documento Obrigatório
A5: Alimentação | B5: 120 | C5: Não | D5: Nota Fiscal / Cupom Fiscal Detalhado
A6: Hospedagem | B6: 500 | C6: Sim | D6: Nota Fiscal Hoteleira Discriminada
A7: Passagem Aérea | B7: 1500 | C7: Sim | D7: Bilhete de Passagem + E-ticket
A8: Passagem Rodoviária | B8: 250 | C8: Não | D8: Bilhete de Passagem Rodoviário
A9: Combustível | B9: 300 | C9: Não | D9: Cupom Fiscal + Relatório de KM
A10: Estacionamento | B10: 80 | C10: Não | D10: Comprovante / Recibo de Estacionamento
A11: Táxi | B11: 100 | C11: Não | D11: Recibo / Nota Fiscal de Serviço
A12: Uber | B12: 150 | C12: Não | D12: Recibo do Aplicativo em PDF
A13: Pedágio | B13: 60 | C13: Não | D13: Comprovante do Pedágio / Extrato Sem Parar
A14: Material de Escritório | B14: 200 | C14: Não | D14: Nota Fiscal com CNPJ da Empresa
A15: Cursos | B15: 2000 | C15: Sim | D15: Nota Fiscal + Certificado de Conclusão
A16: Eventos Corporativos | B16: 2500 | C16: Sim | D16: Nota Fiscal + Convite / Folder do Evento

Sheet Dashboard
A1: Vida Plena S.A. — Painel Executivo de Prestação de Contas
A2: Indicadores Geral de Reembolsos e Visão Consolidada
A4: Total de Solicitações | C4: Total Aprovado (Qtd) | E4: Total Rejeitado (Qtd) | G4: Total Pendente (Qtd)
A5: =COUNTA('Prestação de Contas'!A5:A54) | C5: =COUNTIF('Prestação de Contas'!Q5:Q54, "Aprovado") | E5: =COUNTIF('Prestação de Contas'!Q5:Q54, "Rejeitado") | G5: =COUNTIF('Prestação de Contas'!Q5:Q54, "Pendente")
A7: Valor Total Solicitado | C7: Valor Total Aprovado | E7: Valor Total Rejeitado | G7: Média por Solicitação
A8: =SUM('Prestação de Contas'!M5:M54) | C8: =SUMIF('Prestação de Contas'!Q5:Q54, "Aprovado", 'Prestação de Contas'!M5:M54) | E8: =SUMIF('Prestação de Contas'!Q5:Q54, "Rejeitado", 'Prestação de Contas'!M5:M54) | G8: =AVERAGE('Prestação de Contas'!M5:M54)
A10: Destaques & Métricas Chave
A11: Métrica | B11: Resultado
A12: Departamento com Maior Gasto | B12: =INDEX(A15:A20, MATCH(MAX(B15:B20), B15:B20, 0))
A13: Tipo de Despesa Mais Frequente | B13: =INDEX(D15:D26, MATCH(MAX(E15:E26), E15:E26, 0))
A14: Departamento | B14: Total Gasto (R$) | D14: Tipo de Despesa | E14: Qtd. Solicitações | F14: Total Gasto (R$)
A15: Comercial | B15: =SUMIF('Prestação de Contas'!F5:F54, "Comercial", 'Prestação de Contas'!M5:M54) | D15: Alimentação | E15: =COUNTIF('Prestação de Contas'!K5:K54, "Alimentação") | F15: =SUMIF('Prestação de Contas'!K5:K54, "Alimentação", 'Prestação de Contas'!M5:M54)
A16: TI | B16: =SUMIF('Prestação de Contas'!F5:F54, "TI", 'Prestação de Contas'!M5:M54) | D16: Hospedagem | E16: =COUNTIF('Prestação de Contas'!K5:K54, "Hospedagem") | F16: =SUMIF('Prestação de Contas'!K5:K54, "Hospedagem", 'Prestação de Contas'!M5:M54)
A17: Financeiro | B17: =SUMIF('Prestação de Contas'!F5:F54, "Financeiro", 'Prestação de Contas'!M5:M54) | D17: Passagem aérea | E17: =COUNTIF('Prestação de Contas'!K5:K54, "Passagem aérea") | F17: =SUMIF('Prestação de Contas'!K5:K54, "Passagem aérea", 'Prestação de Contas'!M5:M54)
A18: RH | B18: =SUMIF('Prestação de Contas'!F5:F54, "RH", 'Prestação de Contas'!M5:M54) | D18: Passagem rodoviária | E18: =COUNTIF('Prestação de Contas'!K5:K54, "Passagem rodoviária") | F18: =SUMIF('Prestação de Contas'!K5:K54, "Passagem rodoviária", 'Prestação de Contas'!M5:M54)
A19: Compliance | B19: =SUMIF('Prestação de Contas'!F5:F54, "Compliance", 'Prestação de Contas'!M5:M54) | D19: Combustível | E19: =COUNTIF('Prestação de Contas'!K5:K54, "Combustível") | F19: =SUMIF('Prestação de Contas'!K5:K54, "Combustível", 'Prestação de Contas'!M5:M54)
A20: Comunicação | B20: =SUMIF('Prestação de Contas'!F5:F54, "Comunicação", 'Prestação de Contas'!M5:M54) | D20: Estacionamento | E20: =COUNTIF('Prestação de Contas'!K5:K54, "Estacionamento") | F20: =SUMIF('Prestação de Contas'!K5:K54, "Estacionamento", 'Prestação de Contas'!M5:M54)
D21: Táxi | E21: =COUNTIF('Prestação de Contas'!K5:K54, "Táxi") | F21: =SUMIF('Prestação de Contas'!K5:K54, "Táxi", 'Prestação de Contas'!M5:M54)
A22: Status | B22: Qtd | D22: Uber | E22: =COUNTIF('Prestação de Contas'!K5:K54, "Uber") | F22: =SUMIF('Prestação de Contas'!K5:K54, "Uber", 'Prestação de Contas'!M5:M54)
A23: Aprovado | B23: =COUNTIF('Prestação de Contas'!Q5:Q54, "Aprovado") | D23: Pedágio | E23: =COUNTIF('Prestação de Contas'!K5:K54, "Pedágio") | F23: =SUMIF('Prestação de Contas'!K5:K54, "Pedágio", 'Prestação de Contas'!M5:M54)
A24: Pendente | B24: =COUNTIF('Prestação de Contas'!Q5:Q54, "Pendente") | D24: Material de escritório | E24: =COUNTIF('Prestação de Contas'!K5:K54, "Material de escritório") | F24: =SUMIF('Prestação de Contas'!K5:K54, "Material de escritório", 'Prestação de Contas'!M5:M54)
A25: Rejeitado | B25: =COUNTIF('Prestação de Contas'!Q5:Q54, "Rejeitado") | D25: Cursos | E25: =COUNTIF('Prestação de Contas'!K5:K54, "Cursos") | F25: =SUMIF('Prestação de Contas'!K5:K54, "Cursos", 'Prestação de Contas'!M5:M54)
D26: Eventos corporativos | E26: =COUNTIF('Prestação de Contas'!K5:K54, "Eventos corporativos") | F26: =SUMIF('Prestação de Contas'!K5:K54, "Eventos corporativos", 'Prestação de Contas'!M5:M54)
